[2023-08-16T09:09:18.720+0000] {taskinstance.py:1087} INFO - Dependencies all met for <TaskInstance: rapid_api_v1.load_db scheduled__2023-08-14T00:00:00+00:00 [queued]>
[2023-08-16T09:09:18.729+0000] {taskinstance.py:1087} INFO - Dependencies all met for <TaskInstance: rapid_api_v1.load_db scheduled__2023-08-14T00:00:00+00:00 [queued]>
[2023-08-16T09:09:18.730+0000] {taskinstance.py:1283} INFO - 
--------------------------------------------------------------------------------
[2023-08-16T09:09:18.731+0000] {taskinstance.py:1284} INFO - Starting attempt 1 of 1
[2023-08-16T09:09:18.731+0000] {taskinstance.py:1285} INFO - 
--------------------------------------------------------------------------------
[2023-08-16T09:09:18.739+0000] {taskinstance.py:1304} INFO - Executing <Task(PythonOperator): load_db> on 2023-08-14 00:00:00+00:00
[2023-08-16T09:09:18.745+0000] {standard_task_runner.py:55} INFO - Started process 547 to run task
[2023-08-16T09:09:18.749+0000] {standard_task_runner.py:82} INFO - Running: ['***', 'tasks', 'run', 'rapid_api_v1', 'load_db', 'scheduled__2023-08-14T00:00:00+00:00', '--job-id', '49', '--raw', '--subdir', 'DAGS_FOLDER/jobs_etl.py', '--cfg-path', '/tmp/tmpfw6a31u3']
[2023-08-16T09:09:18.750+0000] {standard_task_runner.py:83} INFO - Job 49: Subtask load_db
[2023-08-16T09:09:18.809+0000] {task_command.py:389} INFO - Running <TaskInstance: rapid_api_v1.load_db scheduled__2023-08-14T00:00:00+00:00 [running]> on host 17c4b1dd2309
[2023-08-16T09:09:18.885+0000] {taskinstance.py:1513} INFO - Exporting the following env vars:
AIRFLOW_CTX_DAG_OWNER=***
AIRFLOW_CTX_DAG_ID=rapid_api_v1
AIRFLOW_CTX_TASK_ID=load_db
AIRFLOW_CTX_EXECUTION_DATE=2023-08-14T00:00:00+00:00
AIRFLOW_CTX_TRY_NUMBER=1
AIRFLOW_CTX_DAG_RUN_ID=scheduled__2023-08-14T00:00:00+00:00
[2023-08-16T09:09:18.917+0000] {taskinstance.py:1772} ERROR - Task failed with exception
Traceback (most recent call last):
  File "/home/airflow/.local/lib/python3.7/site-packages/airflow/operators/python.py", line 175, in execute
    return_value = self.execute_callable()
  File "/home/airflow/.local/lib/python3.7/site-packages/airflow/operators/python.py", line 192, in execute_callable
    return self.python_callable(*self.op_args, **self.op_kwargs)
  File "/opt/airflow/dags/jobs_etl.py", line 122, in to_sql_task
    df.to_sql(table_name, engine)
  File "/home/airflow/.local/lib/python3.7/site-packages/pandas/core/generic.py", line 2882, in to_sql
    method=method,
  File "/home/airflow/.local/lib/python3.7/site-packages/pandas/io/sql.py", line 728, in to_sql
    **engine_kwargs,
  File "/home/airflow/.local/lib/python3.7/site-packages/pandas/io/sql.py", line 1758, in to_sql
    dtype=dtype,
  File "/home/airflow/.local/lib/python3.7/site-packages/pandas/io/sql.py", line 1650, in prep_table
    table.create()
  File "/home/airflow/.local/lib/python3.7/site-packages/pandas/io/sql.py", line 858, in create
    raise ValueError(f"Table '{self.name}' already exists.")
ValueError: Table 'new_rapid_api_jobs' already exists.
[2023-08-16T09:09:18.931+0000] {taskinstance.py:1327} INFO - Marking task as FAILED. dag_id=rapid_api_v1, task_id=load_db, execution_date=20230814T000000, start_date=20230816T090918, end_date=20230816T090918
[2023-08-16T09:09:18.941+0000] {standard_task_runner.py:105} ERROR - Failed to execute job 49 for task load_db (Table 'new_rapid_api_jobs' already exists.; 547)
[2023-08-16T09:09:18.961+0000] {local_task_job.py:159} INFO - Task exited with return code 1
[2023-08-16T09:09:18.980+0000] {taskinstance.py:2582} INFO - 0 downstream tasks scheduled from follow-on schedule check
