[2023-08-16T20:00:34.856+0000] {taskinstance.py:1087} INFO - Dependencies all met for <TaskInstance: random_user_v1.extract_relevant_credentials scheduled__2023-08-02T00:00:00+00:00 [queued]>
[2023-08-16T20:00:34.865+0000] {taskinstance.py:1087} INFO - Dependencies all met for <TaskInstance: random_user_v1.extract_relevant_credentials scheduled__2023-08-02T00:00:00+00:00 [queued]>
[2023-08-16T20:00:34.867+0000] {taskinstance.py:1283} INFO - 
--------------------------------------------------------------------------------
[2023-08-16T20:00:34.868+0000] {taskinstance.py:1284} INFO - Starting attempt 2 of 6
[2023-08-16T20:00:34.869+0000] {taskinstance.py:1285} INFO - 
--------------------------------------------------------------------------------
[2023-08-16T20:00:34.880+0000] {taskinstance.py:1304} INFO - Executing <Task(PythonOperator): extract_relevant_credentials> on 2023-08-02 00:00:00+00:00
[2023-08-16T20:00:34.887+0000] {standard_task_runner.py:55} INFO - Started process 2084 to run task
[2023-08-16T20:00:34.899+0000] {standard_task_runner.py:82} INFO - Running: ['***', 'tasks', 'run', 'random_user_v1', 'extract_relevant_credentials', 'scheduled__2023-08-02T00:00:00+00:00', '--job-id', '25', '--raw', '--subdir', 'DAGS_FOLDER/random_user_etl.py', '--cfg-path', '/tmp/tmpxm5eip5_']
[2023-08-16T20:00:34.901+0000] {standard_task_runner.py:83} INFO - Job 25: Subtask extract_relevant_credentials
[2023-08-16T20:00:34.983+0000] {task_command.py:389} INFO - Running <TaskInstance: random_user_v1.extract_relevant_credentials scheduled__2023-08-02T00:00:00+00:00 [running]> on host c0eab1525b89
[2023-08-16T20:00:35.084+0000] {taskinstance.py:1513} INFO - Exporting the following env vars:
AIRFLOW_CTX_DAG_OWNER=mujjeeb
AIRFLOW_CTX_DAG_ID=random_user_v1
AIRFLOW_CTX_TASK_ID=extract_relevant_credentials
AIRFLOW_CTX_EXECUTION_DATE=2023-08-02T00:00:00+00:00
AIRFLOW_CTX_TRY_NUMBER=2
AIRFLOW_CTX_DAG_RUN_ID=scheduled__2023-08-02T00:00:00+00:00
[2023-08-16T20:00:35.087+0000] {python.py:177} INFO - Done. Returned value was: (['Olivia', 'Elizabeth', 'Oscar', 'Stanley', 'Miloš', 'Perry', 'Atiksh', "P'ier", 'Ilse', 'Walter'], ['Simon', 'Solsvik', 'Núñez', 'Davis', 'Erceg', 'Chapman', 'Prajapati', 'Dunin-Borkovskiy', 'Archuleta', 'Skogland'], ['female', 'female', 'male', 'male', 'male', 'male', 'male', 'male', 'female', 'male'], ['olivia.simon@example.com', 'elizabeth.solsvik@example.com', 'oscar.nunez@example.com', 'stanley.davis@example.com', 'milos.erceg@example.com', 'perry.chapman@example.com', 'atiksh.prajapati@example.com', "p'ier.dunin-borkovskiy@example.com", 'ilse.archuleta@example.com', 'walter.skogland@example.com'], [datetime.date(1950, 3, 4), datetime.date(1948, 9, 1), datetime.date(1966, 7, 30), datetime.date(1975, 4, 5), datetime.date(1986, 7, 26), datetime.date(1945, 11, 3), datetime.date(1954, 6, 14), datetime.date(1965, 12, 13), datetime.date(1967, 6, 9), datetime.date(1948, 1, 24)], ['France', 'Norway', 'Spain', 'Australia', 'Serbia', 'Australia', 'India', 'Ukraine', 'Mexico', 'Norway'], ['House 1299, Quai Chauveau', 'House 6248, Innspurten', 'House 2913, Calle de Téllez', 'House 2538, Brown Terrace', 'House 5894, Virska', 'House 1134, Avondale Ave', 'House 7569, Somwar Peth', 'House 6969, Radgospna', 'House 2272, Diagonal Soria', 'House 6113, Måkeveien'], ['Nanterre', 'Glærem', 'Lorca', 'Tamworth', 'Ćićevac', 'Mildura', 'Madurai', 'Feodosiya', 'Jesús Carranza', 'Lillesand'], ['Morbihan', 'Nordland', 'Ceuta', 'Northern Territory', 'Moravica', 'Queensland', 'Himachal Pradesh', 'Ternopilska', 'Durango', 'Buskerud'], [55226, '7042', 25317, 4382, 28180, 8555, 59226, 79186, 62164, '1556'], ['02-88-45-82-54', '88104335', '981-773-383', '07-2310-7500', '033-8005-197', '09-3215-4376', '7052486692', '(066) L08-5280', '(663) 785 6232', '77101766'], ['06-90-92-47-29', '95657518', '646-071-126', '0481-493-501', '068-5787-925', '0442-473-045', '9516346204', '(067) G80-9356', '(624) 408 3996', '42872936'])
[2023-08-16T20:00:35.097+0000] {taskinstance.py:1772} ERROR - Task failed with exception
Traceback (most recent call last):
  File "/home/airflow/.local/lib/python3.7/site-packages/airflow/utils/session.py", line 72, in wrapper
    return func(*args, **kwargs)
  File "/home/airflow/.local/lib/python3.7/site-packages/airflow/models/taskinstance.py", line 2301, in xcom_push
    session=session,
  File "/home/airflow/.local/lib/python3.7/site-packages/airflow/utils/session.py", line 72, in wrapper
    return func(*args, **kwargs)
  File "/home/airflow/.local/lib/python3.7/site-packages/airflow/models/xcom.py", line 240, in set
    map_index=map_index,
  File "/home/airflow/.local/lib/python3.7/site-packages/airflow/models/xcom.py", line 627, in serialize_value
    return json.dumps(value, cls=XComEncoder).encode("UTF-8")
  File "/usr/local/lib/python3.7/json/__init__.py", line 238, in dumps
    **kw).encode(obj)
  File "/home/airflow/.local/lib/python3.7/site-packages/airflow/utils/json.py", line 176, in encode
    return super().encode(o)
  File "/usr/local/lib/python3.7/json/encoder.py", line 199, in encode
    chunks = self.iterencode(o, _one_shot=True)
  File "/usr/local/lib/python3.7/json/encoder.py", line 257, in iterencode
    return _iterencode(o, 0)
  File "/home/airflow/.local/lib/python3.7/site-packages/airflow/utils/json.py", line 153, in default
    CLASSNAME: o.__module__ + "." + o.__class__.__qualname__,
AttributeError: 'datetime.date' object has no attribute '__module__'
[2023-08-16T20:00:35.108+0000] {taskinstance.py:1327} INFO - Marking task as UP_FOR_RETRY. dag_id=random_user_v1, task_id=extract_relevant_credentials, execution_date=20230802T000000, start_date=20230816T200034, end_date=20230816T200035
[2023-08-16T20:00:35.117+0000] {standard_task_runner.py:105} ERROR - Failed to execute job 25 for task extract_relevant_credentials ('datetime.date' object has no attribute '__module__'; 2084)
[2023-08-16T20:00:35.145+0000] {local_task_job.py:159} INFO - Task exited with return code 1
[2023-08-16T20:00:35.167+0000] {taskinstance.py:2582} INFO - 0 downstream tasks scheduled from follow-on schedule check
