[2023-08-17T00:14:43.601+0000] {processor.py:153} INFO - Started process (PID=1901) to work on /opt/airflow/dags/random_user_etl.py
[2023-08-17T00:14:43.608+0000] {processor.py:743} INFO - Processing file /opt/airflow/dags/random_user_etl.py for tasks to queue
[2023-08-17T00:14:43.617+0000] {logging_mixin.py:137} INFO - [2023-08-17T00:14:43.616+0000] {dagbag.py:538} INFO - Filling up the DagBag from /opt/airflow/dags/random_user_etl.py
[2023-08-17T00:15:03.933+0000] {logging_mixin.py:137} INFO - [2023-08-17T00:15:03.930+0000] {dagbag.py:343} ERROR - Failed to import: /opt/airflow/dags/random_user_etl.py
Traceback (most recent call last):
  File "/home/airflow/.local/lib/python3.7/site-packages/airflow/models/dagbag.py", line 339, in parse
    loader.exec_module(new_module)
  File "<frozen importlib._bootstrap_external>", line 728, in exec_module
  File "<frozen importlib._bootstrap>", line 219, in _call_with_frames_removed
  File "/opt/airflow/dags/random_user_etl.py", line 101, in <module>
    start_date=datetime(2023,16,1),
ValueError: month must be in 1..12
[2023-08-17T00:15:03.951+0000] {processor.py:755} WARNING - No viable dags retrieved from /opt/airflow/dags/random_user_etl.py
[2023-08-17T00:15:03.973+0000] {processor.py:175} INFO - Processing /opt/airflow/dags/random_user_etl.py took 20.374 seconds
[2023-08-17T00:15:34.238+0000] {processor.py:153} INFO - Started process (PID=1951) to work on /opt/airflow/dags/random_user_etl.py
[2023-08-17T00:15:34.240+0000] {processor.py:743} INFO - Processing file /opt/airflow/dags/random_user_etl.py for tasks to queue
[2023-08-17T00:15:34.241+0000] {logging_mixin.py:137} INFO - [2023-08-17T00:15:34.241+0000] {dagbag.py:538} INFO - Filling up the DagBag from /opt/airflow/dags/random_user_etl.py
[2023-08-17T00:15:38.422+0000] {logging_mixin.py:137} INFO - [2023-08-17T00:15:38.415+0000] {dagbag.py:343} ERROR - Failed to import: /opt/airflow/dags/random_user_etl.py
Traceback (most recent call last):
  File "/home/airflow/.local/lib/python3.7/site-packages/urllib3/connectionpool.py", line 710, in urlopen
    chunked=chunked,
  File "/home/airflow/.local/lib/python3.7/site-packages/urllib3/connectionpool.py", line 449, in _make_request
    six.raise_from(e, None)
  File "<string>", line 3, in raise_from
  File "/home/airflow/.local/lib/python3.7/site-packages/urllib3/connectionpool.py", line 444, in _make_request
    httplib_response = conn.getresponse()
  File "/usr/local/lib/python3.7/http/client.py", line 1373, in getresponse
    response.begin()
  File "/usr/local/lib/python3.7/http/client.py", line 319, in begin
    version, status, reason = self._read_status()
  File "/usr/local/lib/python3.7/http/client.py", line 288, in _read_status
    raise RemoteDisconnected("Remote end closed connection without"
http.client.RemoteDisconnected: Remote end closed connection without response

During handling of the above exception, another exception occurred:

Traceback (most recent call last):
  File "/home/airflow/.local/lib/python3.7/site-packages/requests/adapters.py", line 499, in send
    timeout=timeout,
  File "/home/airflow/.local/lib/python3.7/site-packages/urllib3/connectionpool.py", line 788, in urlopen
    method, url, error=e, _pool=self, _stacktrace=sys.exc_info()[2]
  File "/home/airflow/.local/lib/python3.7/site-packages/urllib3/util/retry.py", line 550, in increment
    raise six.reraise(type(error), error, _stacktrace)
  File "/home/airflow/.local/lib/python3.7/site-packages/urllib3/packages/six.py", line 769, in reraise
    raise value.with_traceback(tb)
  File "/home/airflow/.local/lib/python3.7/site-packages/urllib3/connectionpool.py", line 710, in urlopen
    chunked=chunked,
  File "/home/airflow/.local/lib/python3.7/site-packages/urllib3/connectionpool.py", line 449, in _make_request
    six.raise_from(e, None)
  File "<string>", line 3, in raise_from
  File "/home/airflow/.local/lib/python3.7/site-packages/urllib3/connectionpool.py", line 444, in _make_request
    httplib_response = conn.getresponse()
  File "/usr/local/lib/python3.7/http/client.py", line 1373, in getresponse
    response.begin()
  File "/usr/local/lib/python3.7/http/client.py", line 319, in begin
    version, status, reason = self._read_status()
  File "/usr/local/lib/python3.7/http/client.py", line 288, in _read_status
    raise RemoteDisconnected("Remote end closed connection without"
urllib3.exceptions.ProtocolError: ('Connection aborted.', RemoteDisconnected('Remote end closed connection without response'))

During handling of the above exception, another exception occurred:

Traceback (most recent call last):
  File "/home/airflow/.local/lib/python3.7/site-packages/airflow/models/dagbag.py", line 339, in parse
    loader.exec_module(new_module)
  File "<frozen importlib._bootstrap_external>", line 728, in exec_module
  File "<frozen importlib._bootstrap>", line 219, in _call_with_frames_removed
  File "/opt/airflow/dags/random_user_etl.py", line 85, in <module>
    data.append(get_data_from_api())
  File "/opt/airflow/dags/random_user_etl.py", line 14, in get_data_from_api
    response = requests.get(url)
  File "/home/airflow/.local/lib/python3.7/site-packages/requests/api.py", line 73, in get
    return request("get", url, params=params, **kwargs)
  File "/home/airflow/.local/lib/python3.7/site-packages/requests/api.py", line 59, in request
    return session.request(method=method, url=url, **kwargs)
  File "/home/airflow/.local/lib/python3.7/site-packages/requests/sessions.py", line 587, in request
    resp = self.send(prep, **send_kwargs)
  File "/home/airflow/.local/lib/python3.7/site-packages/requests/sessions.py", line 701, in send
    r = adapter.send(request, **kwargs)
  File "/home/airflow/.local/lib/python3.7/site-packages/requests/adapters.py", line 547, in send
    raise ConnectionError(err, request=request)
requests.exceptions.ConnectionError: ('Connection aborted.', RemoteDisconnected('Remote end closed connection without response'))
[2023-08-17T00:15:38.426+0000] {processor.py:755} WARNING - No viable dags retrieved from /opt/airflow/dags/random_user_etl.py
[2023-08-17T00:15:38.448+0000] {processor.py:175} INFO - Processing /opt/airflow/dags/random_user_etl.py took 4.213 seconds
[2023-08-17T01:19:09.828+0000] {processor.py:153} INFO - Started process (PID=1965) to work on /opt/airflow/dags/random_user_etl.py
[2023-08-17T01:19:09.830+0000] {processor.py:743} INFO - Processing file /opt/airflow/dags/random_user_etl.py for tasks to queue
[2023-08-17T01:19:09.832+0000] {logging_mixin.py:137} INFO - [2023-08-17T01:19:09.832+0000] {dagbag.py:538} INFO - Filling up the DagBag from /opt/airflow/dags/random_user_etl.py
[2023-08-17T01:19:16.888+0000] {logging_mixin.py:137} INFO - [2023-08-17T01:19:16.882+0000] {dagbag.py:343} ERROR - Failed to import: /opt/airflow/dags/random_user_etl.py
Traceback (most recent call last):
  File "/home/airflow/.local/lib/python3.7/site-packages/airflow/models/dagbag.py", line 339, in parse
    loader.exec_module(new_module)
  File "<frozen importlib._bootstrap_external>", line 728, in exec_module
  File "<frozen importlib._bootstrap>", line 219, in _call_with_frames_removed
  File "/opt/airflow/dags/random_user_etl.py", line 101, in <module>
    start_date=datetime(2023,16,1),
ValueError: month must be in 1..12
[2023-08-17T01:19:16.890+0000] {processor.py:755} WARNING - No viable dags retrieved from /opt/airflow/dags/random_user_etl.py
[2023-08-17T01:19:16.914+0000] {processor.py:175} INFO - Processing /opt/airflow/dags/random_user_etl.py took 7.089 seconds
[2023-08-17T01:19:47.321+0000] {processor.py:153} INFO - Started process (PID=2003) to work on /opt/airflow/dags/random_user_etl.py
[2023-08-17T01:19:47.323+0000] {processor.py:743} INFO - Processing file /opt/airflow/dags/random_user_etl.py for tasks to queue
[2023-08-17T01:19:47.325+0000] {logging_mixin.py:137} INFO - [2023-08-17T01:19:47.325+0000] {dagbag.py:538} INFO - Filling up the DagBag from /opt/airflow/dags/random_user_etl.py
[2023-08-17T01:19:50.863+0000] {logging_mixin.py:137} INFO - [2023-08-17T01:19:50.861+0000] {dagbag.py:343} ERROR - Failed to import: /opt/airflow/dags/random_user_etl.py
Traceback (most recent call last):
  File "/home/airflow/.local/lib/python3.7/site-packages/airflow/models/dagbag.py", line 339, in parse
    loader.exec_module(new_module)
  File "<frozen importlib._bootstrap_external>", line 728, in exec_module
  File "<frozen importlib._bootstrap>", line 219, in _call_with_frames_removed
  File "/opt/airflow/dags/random_user_etl.py", line 101, in <module>
    start_date=datetime(2023,16,1),
ValueError: month must be in 1..12
[2023-08-17T01:19:50.865+0000] {processor.py:755} WARNING - No viable dags retrieved from /opt/airflow/dags/random_user_etl.py
[2023-08-17T01:19:50.883+0000] {processor.py:175} INFO - Processing /opt/airflow/dags/random_user_etl.py took 3.569 seconds
[2023-08-17T02:11:55.600+0000] {processor.py:153} INFO - Started process (PID=2028) to work on /opt/airflow/dags/random_user_etl.py
[2023-08-17T02:11:55.604+0000] {processor.py:743} INFO - Processing file /opt/airflow/dags/random_user_etl.py for tasks to queue
[2023-08-17T02:11:55.606+0000] {logging_mixin.py:137} INFO - [2023-08-17T02:11:55.606+0000] {dagbag.py:538} INFO - Filling up the DagBag from /opt/airflow/dags/random_user_etl.py
[2023-08-17T02:12:03.458+0000] {logging_mixin.py:137} INFO - [2023-08-17T02:12:03.434+0000] {dagbag.py:343} ERROR - Failed to import: /opt/airflow/dags/random_user_etl.py
Traceback (most recent call last):
  File "/home/airflow/.local/lib/python3.7/site-packages/urllib3/connectionpool.py", line 710, in urlopen
    chunked=chunked,
  File "/home/airflow/.local/lib/python3.7/site-packages/urllib3/connectionpool.py", line 449, in _make_request
    six.raise_from(e, None)
  File "<string>", line 3, in raise_from
  File "/home/airflow/.local/lib/python3.7/site-packages/urllib3/connectionpool.py", line 444, in _make_request
    httplib_response = conn.getresponse()
  File "/usr/local/lib/python3.7/http/client.py", line 1373, in getresponse
    response.begin()
  File "/usr/local/lib/python3.7/http/client.py", line 319, in begin
    version, status, reason = self._read_status()
  File "/usr/local/lib/python3.7/http/client.py", line 288, in _read_status
    raise RemoteDisconnected("Remote end closed connection without"
http.client.RemoteDisconnected: Remote end closed connection without response

During handling of the above exception, another exception occurred:

Traceback (most recent call last):
  File "/home/airflow/.local/lib/python3.7/site-packages/requests/adapters.py", line 499, in send
    timeout=timeout,
  File "/home/airflow/.local/lib/python3.7/site-packages/urllib3/connectionpool.py", line 788, in urlopen
    method, url, error=e, _pool=self, _stacktrace=sys.exc_info()[2]
  File "/home/airflow/.local/lib/python3.7/site-packages/urllib3/util/retry.py", line 550, in increment
    raise six.reraise(type(error), error, _stacktrace)
  File "/home/airflow/.local/lib/python3.7/site-packages/urllib3/packages/six.py", line 769, in reraise
    raise value.with_traceback(tb)
  File "/home/airflow/.local/lib/python3.7/site-packages/urllib3/connectionpool.py", line 710, in urlopen
    chunked=chunked,
  File "/home/airflow/.local/lib/python3.7/site-packages/urllib3/connectionpool.py", line 449, in _make_request
    six.raise_from(e, None)
  File "<string>", line 3, in raise_from
  File "/home/airflow/.local/lib/python3.7/site-packages/urllib3/connectionpool.py", line 444, in _make_request
    httplib_response = conn.getresponse()
  File "/usr/local/lib/python3.7/http/client.py", line 1373, in getresponse
    response.begin()
  File "/usr/local/lib/python3.7/http/client.py", line 319, in begin
    version, status, reason = self._read_status()
  File "/usr/local/lib/python3.7/http/client.py", line 288, in _read_status
    raise RemoteDisconnected("Remote end closed connection without"
urllib3.exceptions.ProtocolError: ('Connection aborted.', RemoteDisconnected('Remote end closed connection without response'))

During handling of the above exception, another exception occurred:

Traceback (most recent call last):
  File "/home/airflow/.local/lib/python3.7/site-packages/airflow/models/dagbag.py", line 339, in parse
    loader.exec_module(new_module)
  File "<frozen importlib._bootstrap_external>", line 728, in exec_module
  File "<frozen importlib._bootstrap>", line 219, in _call_with_frames_removed
  File "/opt/airflow/dags/random_user_etl.py", line 85, in <module>
    data.append(get_data_from_api())
  File "/opt/airflow/dags/random_user_etl.py", line 14, in get_data_from_api
    response = requests.get(url)
  File "/home/airflow/.local/lib/python3.7/site-packages/requests/api.py", line 73, in get
    return request("get", url, params=params, **kwargs)
  File "/home/airflow/.local/lib/python3.7/site-packages/requests/api.py", line 59, in request
    return session.request(method=method, url=url, **kwargs)
  File "/home/airflow/.local/lib/python3.7/site-packages/requests/sessions.py", line 587, in request
    resp = self.send(prep, **send_kwargs)
  File "/home/airflow/.local/lib/python3.7/site-packages/requests/sessions.py", line 701, in send
    r = adapter.send(request, **kwargs)
  File "/home/airflow/.local/lib/python3.7/site-packages/requests/adapters.py", line 547, in send
    raise ConnectionError(err, request=request)
requests.exceptions.ConnectionError: ('Connection aborted.', RemoteDisconnected('Remote end closed connection without response'))
[2023-08-17T02:12:03.461+0000] {processor.py:755} WARNING - No viable dags retrieved from /opt/airflow/dags/random_user_etl.py
[2023-08-17T02:12:03.493+0000] {processor.py:175} INFO - Processing /opt/airflow/dags/random_user_etl.py took 7.898 seconds
[2023-08-17T03:04:55.009+0000] {processor.py:153} INFO - Started process (PID=2066) to work on /opt/airflow/dags/random_user_etl.py
[2023-08-17T03:04:55.014+0000] {processor.py:743} INFO - Processing file /opt/airflow/dags/random_user_etl.py for tasks to queue
[2023-08-17T03:04:55.015+0000] {logging_mixin.py:137} INFO - [2023-08-17T03:04:55.015+0000] {dagbag.py:538} INFO - Filling up the DagBag from /opt/airflow/dags/random_user_etl.py
[2023-08-17T03:05:02.067+0000] {logging_mixin.py:137} INFO - [2023-08-17T03:05:02.058+0000] {dagbag.py:343} ERROR - Failed to import: /opt/airflow/dags/random_user_etl.py
Traceback (most recent call last):
  File "/home/airflow/.local/lib/python3.7/site-packages/airflow/models/dagbag.py", line 339, in parse
    loader.exec_module(new_module)
  File "<frozen importlib._bootstrap_external>", line 728, in exec_module
  File "<frozen importlib._bootstrap>", line 219, in _call_with_frames_removed
  File "/opt/airflow/dags/random_user_etl.py", line 101, in <module>
    start_date=datetime(2023,16,1),
ValueError: month must be in 1..12
[2023-08-17T03:05:02.070+0000] {processor.py:755} WARNING - No viable dags retrieved from /opt/airflow/dags/random_user_etl.py
[2023-08-17T03:05:02.100+0000] {processor.py:175} INFO - Processing /opt/airflow/dags/random_user_etl.py took 7.095 seconds
[2023-08-17T03:05:32.478+0000] {processor.py:153} INFO - Started process (PID=2105) to work on /opt/airflow/dags/random_user_etl.py
[2023-08-17T03:05:32.481+0000] {processor.py:743} INFO - Processing file /opt/airflow/dags/random_user_etl.py for tasks to queue
[2023-08-17T03:05:32.482+0000] {logging_mixin.py:137} INFO - [2023-08-17T03:05:32.482+0000] {dagbag.py:538} INFO - Filling up the DagBag from /opt/airflow/dags/random_user_etl.py
[2023-08-17T03:05:37.071+0000] {logging_mixin.py:137} INFO - [2023-08-17T03:05:37.068+0000] {dagbag.py:343} ERROR - Failed to import: /opt/airflow/dags/random_user_etl.py
Traceback (most recent call last):
  File "/home/airflow/.local/lib/python3.7/site-packages/airflow/models/dagbag.py", line 339, in parse
    loader.exec_module(new_module)
  File "<frozen importlib._bootstrap_external>", line 728, in exec_module
  File "<frozen importlib._bootstrap>", line 219, in _call_with_frames_removed
  File "/opt/airflow/dags/random_user_etl.py", line 101, in <module>
    start_date=datetime(2023,16,1),
ValueError: month must be in 1..12
[2023-08-17T03:05:37.073+0000] {processor.py:755} WARNING - No viable dags retrieved from /opt/airflow/dags/random_user_etl.py
[2023-08-17T03:05:37.094+0000] {processor.py:175} INFO - Processing /opt/airflow/dags/random_user_etl.py took 4.618 seconds
[2023-08-17T04:27:33.451+0000] {processor.py:153} INFO - Started process (PID=2131) to work on /opt/airflow/dags/random_user_etl.py
[2023-08-17T04:27:33.453+0000] {processor.py:743} INFO - Processing file /opt/airflow/dags/random_user_etl.py for tasks to queue
[2023-08-17T04:27:33.454+0000] {logging_mixin.py:137} INFO - [2023-08-17T04:27:33.454+0000] {dagbag.py:538} INFO - Filling up the DagBag from /opt/airflow/dags/random_user_etl.py
[2023-08-17T05:48:58.395+0000] {processor.py:153} INFO - Started process (PID=2169) to work on /opt/airflow/dags/random_user_etl.py
[2023-08-17T05:48:58.398+0000] {processor.py:743} INFO - Processing file /opt/airflow/dags/random_user_etl.py for tasks to queue
[2023-08-17T05:48:58.400+0000] {logging_mixin.py:137} INFO - [2023-08-17T05:48:58.400+0000] {dagbag.py:538} INFO - Filling up the DagBag from /opt/airflow/dags/random_user_etl.py
[2023-08-17T05:49:08.516+0000] {logging_mixin.py:137} INFO - [2023-08-17T05:49:08.513+0000] {dagbag.py:343} ERROR - Failed to import: /opt/airflow/dags/random_user_etl.py
Traceback (most recent call last):
  File "/home/airflow/.local/lib/python3.7/site-packages/airflow/models/dagbag.py", line 339, in parse
    loader.exec_module(new_module)
  File "<frozen importlib._bootstrap_external>", line 728, in exec_module
  File "<frozen importlib._bootstrap>", line 219, in _call_with_frames_removed
  File "/opt/airflow/dags/random_user_etl.py", line 101, in <module>
    start_date=datetime(2023,16,1),
ValueError: month must be in 1..12
[2023-08-17T05:49:08.526+0000] {processor.py:755} WARNING - No viable dags retrieved from /opt/airflow/dags/random_user_etl.py
[2023-08-17T05:49:08.562+0000] {processor.py:175} INFO - Processing /opt/airflow/dags/random_user_etl.py took 10.170 seconds
[2023-08-17T07:29:17.216+0000] {processor.py:153} INFO - Started process (PID=2196) to work on /opt/airflow/dags/random_user_etl.py
[2023-08-17T07:29:17.225+0000] {processor.py:743} INFO - Processing file /opt/airflow/dags/random_user_etl.py for tasks to queue
[2023-08-17T07:29:17.231+0000] {logging_mixin.py:137} INFO - [2023-08-17T07:29:17.231+0000] {dagbag.py:538} INFO - Filling up the DagBag from /opt/airflow/dags/random_user_etl.py
[2023-08-17T07:29:21.072+0000] {logging_mixin.py:137} INFO - [2023-08-17T07:29:21.061+0000] {dagbag.py:343} ERROR - Failed to import: /opt/airflow/dags/random_user_etl.py
Traceback (most recent call last):
  File "/home/airflow/.local/lib/python3.7/site-packages/urllib3/connectionpool.py", line 710, in urlopen
    chunked=chunked,
  File "/home/airflow/.local/lib/python3.7/site-packages/urllib3/connectionpool.py", line 386, in _make_request
    self._validate_conn(conn)
  File "/home/airflow/.local/lib/python3.7/site-packages/urllib3/connectionpool.py", line 1042, in _validate_conn
    conn.connect()
  File "/home/airflow/.local/lib/python3.7/site-packages/urllib3/connection.py", line 424, in connect
    tls_in_tls=tls_in_tls,
  File "/home/airflow/.local/lib/python3.7/site-packages/urllib3/util/ssl_.py", line 450, in ssl_wrap_socket
    sock, context, tls_in_tls, server_hostname=server_hostname
  File "/home/airflow/.local/lib/python3.7/site-packages/urllib3/util/ssl_.py", line 493, in _ssl_wrap_socket_impl
    return ssl_context.wrap_socket(sock, server_hostname=server_hostname)
  File "/usr/local/lib/python3.7/ssl.py", line 423, in wrap_socket
    session=session
  File "/usr/local/lib/python3.7/ssl.py", line 870, in _create
    self.do_handshake()
  File "/usr/local/lib/python3.7/ssl.py", line 1139, in do_handshake
    self._sslobj.do_handshake()
OSError: [Errno 0] Error

During handling of the above exception, another exception occurred:

Traceback (most recent call last):
  File "/home/airflow/.local/lib/python3.7/site-packages/requests/adapters.py", line 499, in send
    timeout=timeout,
  File "/home/airflow/.local/lib/python3.7/site-packages/urllib3/connectionpool.py", line 788, in urlopen
    method, url, error=e, _pool=self, _stacktrace=sys.exc_info()[2]
  File "/home/airflow/.local/lib/python3.7/site-packages/urllib3/util/retry.py", line 550, in increment
    raise six.reraise(type(error), error, _stacktrace)
  File "/home/airflow/.local/lib/python3.7/site-packages/urllib3/packages/six.py", line 769, in reraise
    raise value.with_traceback(tb)
  File "/home/airflow/.local/lib/python3.7/site-packages/urllib3/connectionpool.py", line 710, in urlopen
    chunked=chunked,
  File "/home/airflow/.local/lib/python3.7/site-packages/urllib3/connectionpool.py", line 386, in _make_request
    self._validate_conn(conn)
  File "/home/airflow/.local/lib/python3.7/site-packages/urllib3/connectionpool.py", line 1042, in _validate_conn
    conn.connect()
  File "/home/airflow/.local/lib/python3.7/site-packages/urllib3/connection.py", line 424, in connect
    tls_in_tls=tls_in_tls,
  File "/home/airflow/.local/lib/python3.7/site-packages/urllib3/util/ssl_.py", line 450, in ssl_wrap_socket
    sock, context, tls_in_tls, server_hostname=server_hostname
  File "/home/airflow/.local/lib/python3.7/site-packages/urllib3/util/ssl_.py", line 493, in _ssl_wrap_socket_impl
    return ssl_context.wrap_socket(sock, server_hostname=server_hostname)
  File "/usr/local/lib/python3.7/ssl.py", line 423, in wrap_socket
    session=session
  File "/usr/local/lib/python3.7/ssl.py", line 870, in _create
    self.do_handshake()
  File "/usr/local/lib/python3.7/ssl.py", line 1139, in do_handshake
    self._sslobj.do_handshake()
urllib3.exceptions.ProtocolError: ('Connection aborted.', OSError(0, 'Error'))

During handling of the above exception, another exception occurred:

Traceback (most recent call last):
  File "/home/airflow/.local/lib/python3.7/site-packages/airflow/models/dagbag.py", line 339, in parse
    loader.exec_module(new_module)
  File "<frozen importlib._bootstrap_external>", line 728, in exec_module
  File "<frozen importlib._bootstrap>", line 219, in _call_with_frames_removed
  File "/opt/airflow/dags/random_user_etl.py", line 85, in <module>
    data.append(get_data_from_api())
  File "/opt/airflow/dags/random_user_etl.py", line 14, in get_data_from_api
    response = requests.get(url)
  File "/home/airflow/.local/lib/python3.7/site-packages/requests/api.py", line 73, in get
    return request("get", url, params=params, **kwargs)
  File "/home/airflow/.local/lib/python3.7/site-packages/requests/api.py", line 59, in request
    return session.request(method=method, url=url, **kwargs)
  File "/home/airflow/.local/lib/python3.7/site-packages/requests/sessions.py", line 587, in request
    resp = self.send(prep, **send_kwargs)
  File "/home/airflow/.local/lib/python3.7/site-packages/requests/sessions.py", line 701, in send
    r = adapter.send(request, **kwargs)
  File "/home/airflow/.local/lib/python3.7/site-packages/requests/adapters.py", line 547, in send
    raise ConnectionError(err, request=request)
requests.exceptions.ConnectionError: ('Connection aborted.', OSError(0, 'Error'))
[2023-08-17T07:29:21.080+0000] {processor.py:755} WARNING - No viable dags retrieved from /opt/airflow/dags/random_user_etl.py
[2023-08-17T07:29:21.114+0000] {processor.py:175} INFO - Processing /opt/airflow/dags/random_user_etl.py took 3.903 seconds
[2023-08-17T08:50:54.527+0000] {processor.py:153} INFO - Started process (PID=2234) to work on /opt/airflow/dags/random_user_etl.py
[2023-08-17T08:50:54.531+0000] {processor.py:743} INFO - Processing file /opt/airflow/dags/random_user_etl.py for tasks to queue
[2023-08-17T08:50:54.533+0000] {logging_mixin.py:137} INFO - [2023-08-17T08:50:54.533+0000] {dagbag.py:538} INFO - Filling up the DagBag from /opt/airflow/dags/random_user_etl.py
[2023-08-17T08:51:01.385+0000] {logging_mixin.py:137} INFO - [2023-08-17T08:51:01.367+0000] {dagbag.py:343} ERROR - Failed to import: /opt/airflow/dags/random_user_etl.py
Traceback (most recent call last):
  File "/home/airflow/.local/lib/python3.7/site-packages/urllib3/connectionpool.py", line 710, in urlopen
    chunked=chunked,
  File "/home/airflow/.local/lib/python3.7/site-packages/urllib3/connectionpool.py", line 386, in _make_request
    self._validate_conn(conn)
  File "/home/airflow/.local/lib/python3.7/site-packages/urllib3/connectionpool.py", line 1042, in _validate_conn
    conn.connect()
  File "/home/airflow/.local/lib/python3.7/site-packages/urllib3/connection.py", line 424, in connect
    tls_in_tls=tls_in_tls,
  File "/home/airflow/.local/lib/python3.7/site-packages/urllib3/util/ssl_.py", line 450, in ssl_wrap_socket
    sock, context, tls_in_tls, server_hostname=server_hostname
  File "/home/airflow/.local/lib/python3.7/site-packages/urllib3/util/ssl_.py", line 493, in _ssl_wrap_socket_impl
    return ssl_context.wrap_socket(sock, server_hostname=server_hostname)
  File "/usr/local/lib/python3.7/ssl.py", line 423, in wrap_socket
    session=session
  File "/usr/local/lib/python3.7/ssl.py", line 870, in _create
    self.do_handshake()
  File "/usr/local/lib/python3.7/ssl.py", line 1139, in do_handshake
    self._sslobj.do_handshake()
OSError: [Errno 0] Error

During handling of the above exception, another exception occurred:

Traceback (most recent call last):
  File "/home/airflow/.local/lib/python3.7/site-packages/requests/adapters.py", line 499, in send
    timeout=timeout,
  File "/home/airflow/.local/lib/python3.7/site-packages/urllib3/connectionpool.py", line 788, in urlopen
    method, url, error=e, _pool=self, _stacktrace=sys.exc_info()[2]
  File "/home/airflow/.local/lib/python3.7/site-packages/urllib3/util/retry.py", line 550, in increment
    raise six.reraise(type(error), error, _stacktrace)
  File "/home/airflow/.local/lib/python3.7/site-packages/urllib3/packages/six.py", line 769, in reraise
    raise value.with_traceback(tb)
  File "/home/airflow/.local/lib/python3.7/site-packages/urllib3/connectionpool.py", line 710, in urlopen
    chunked=chunked,
  File "/home/airflow/.local/lib/python3.7/site-packages/urllib3/connectionpool.py", line 386, in _make_request
    self._validate_conn(conn)
  File "/home/airflow/.local/lib/python3.7/site-packages/urllib3/connectionpool.py", line 1042, in _validate_conn
    conn.connect()
  File "/home/airflow/.local/lib/python3.7/site-packages/urllib3/connection.py", line 424, in connect
    tls_in_tls=tls_in_tls,
  File "/home/airflow/.local/lib/python3.7/site-packages/urllib3/util/ssl_.py", line 450, in ssl_wrap_socket
    sock, context, tls_in_tls, server_hostname=server_hostname
  File "/home/airflow/.local/lib/python3.7/site-packages/urllib3/util/ssl_.py", line 493, in _ssl_wrap_socket_impl
    return ssl_context.wrap_socket(sock, server_hostname=server_hostname)
  File "/usr/local/lib/python3.7/ssl.py", line 423, in wrap_socket
    session=session
  File "/usr/local/lib/python3.7/ssl.py", line 870, in _create
    self.do_handshake()
  File "/usr/local/lib/python3.7/ssl.py", line 1139, in do_handshake
    self._sslobj.do_handshake()
urllib3.exceptions.ProtocolError: ('Connection aborted.', OSError(0, 'Error'))

During handling of the above exception, another exception occurred:

Traceback (most recent call last):
  File "/home/airflow/.local/lib/python3.7/site-packages/airflow/models/dagbag.py", line 339, in parse
    loader.exec_module(new_module)
  File "<frozen importlib._bootstrap_external>", line 728, in exec_module
  File "<frozen importlib._bootstrap>", line 219, in _call_with_frames_removed
  File "/opt/airflow/dags/random_user_etl.py", line 85, in <module>
    data.append(get_data_from_api())
  File "/opt/airflow/dags/random_user_etl.py", line 14, in get_data_from_api
    response = requests.get(url)
  File "/home/airflow/.local/lib/python3.7/site-packages/requests/api.py", line 73, in get
    return request("get", url, params=params, **kwargs)
  File "/home/airflow/.local/lib/python3.7/site-packages/requests/api.py", line 59, in request
    return session.request(method=method, url=url, **kwargs)
  File "/home/airflow/.local/lib/python3.7/site-packages/requests/sessions.py", line 587, in request
    resp = self.send(prep, **send_kwargs)
  File "/home/airflow/.local/lib/python3.7/site-packages/requests/sessions.py", line 701, in send
    r = adapter.send(request, **kwargs)
  File "/home/airflow/.local/lib/python3.7/site-packages/requests/adapters.py", line 547, in send
    raise ConnectionError(err, request=request)
requests.exceptions.ConnectionError: ('Connection aborted.', OSError(0, 'Error'))
[2023-08-17T08:51:01.392+0000] {processor.py:755} WARNING - No viable dags retrieved from /opt/airflow/dags/random_user_etl.py
[2023-08-17T08:51:01.421+0000] {processor.py:175} INFO - Processing /opt/airflow/dags/random_user_etl.py took 6.905 seconds
[2023-08-17T10:16:03.640+0000] {processor.py:153} INFO - Started process (PID=2260) to work on /opt/airflow/dags/random_user_etl.py
[2023-08-17T10:16:03.642+0000] {processor.py:743} INFO - Processing file /opt/airflow/dags/random_user_etl.py for tasks to queue
[2023-08-17T10:16:03.643+0000] {logging_mixin.py:137} INFO - [2023-08-17T10:16:03.643+0000] {dagbag.py:538} INFO - Filling up the DagBag from /opt/airflow/dags/random_user_etl.py
[2023-08-17T10:16:07.472+0000] {logging_mixin.py:137} INFO - [2023-08-17T10:16:07.468+0000] {dagbag.py:343} ERROR - Failed to import: /opt/airflow/dags/random_user_etl.py
Traceback (most recent call last):
  File "/home/airflow/.local/lib/python3.7/site-packages/airflow/models/dagbag.py", line 339, in parse
    loader.exec_module(new_module)
  File "<frozen importlib._bootstrap_external>", line 728, in exec_module
  File "<frozen importlib._bootstrap>", line 219, in _call_with_frames_removed
  File "/opt/airflow/dags/random_user_etl.py", line 101, in <module>
    start_date=datetime(2023,16,1),
ValueError: month must be in 1..12
[2023-08-17T10:16:07.474+0000] {processor.py:755} WARNING - No viable dags retrieved from /opt/airflow/dags/random_user_etl.py
[2023-08-17T10:16:07.496+0000] {processor.py:175} INFO - Processing /opt/airflow/dags/random_user_etl.py took 3.861 seconds
[2023-08-17T10:16:37.814+0000] {processor.py:153} INFO - Started process (PID=2298) to work on /opt/airflow/dags/random_user_etl.py
[2023-08-17T10:16:37.817+0000] {processor.py:743} INFO - Processing file /opt/airflow/dags/random_user_etl.py for tasks to queue
[2023-08-17T10:16:37.819+0000] {logging_mixin.py:137} INFO - [2023-08-17T10:16:37.819+0000] {dagbag.py:538} INFO - Filling up the DagBag from /opt/airflow/dags/random_user_etl.py
[2023-08-17T10:16:41.424+0000] {logging_mixin.py:137} INFO - [2023-08-17T10:16:41.419+0000] {dagbag.py:343} ERROR - Failed to import: /opt/airflow/dags/random_user_etl.py
Traceback (most recent call last):
  File "/home/airflow/.local/lib/python3.7/site-packages/airflow/models/dagbag.py", line 339, in parse
    loader.exec_module(new_module)
  File "<frozen importlib._bootstrap_external>", line 728, in exec_module
  File "<frozen importlib._bootstrap>", line 219, in _call_with_frames_removed
  File "/opt/airflow/dags/random_user_etl.py", line 101, in <module>
    start_date=datetime(2023,16,1),
ValueError: month must be in 1..12
[2023-08-17T10:16:41.439+0000] {processor.py:755} WARNING - No viable dags retrieved from /opt/airflow/dags/random_user_etl.py
[2023-08-17T10:16:41.460+0000] {processor.py:175} INFO - Processing /opt/airflow/dags/random_user_etl.py took 3.651 seconds
[2023-08-17T10:17:11.760+0000] {processor.py:153} INFO - Started process (PID=2335) to work on /opt/airflow/dags/random_user_etl.py
[2023-08-17T10:17:11.780+0000] {processor.py:743} INFO - Processing file /opt/airflow/dags/random_user_etl.py for tasks to queue
[2023-08-17T10:17:11.782+0000] {logging_mixin.py:137} INFO - [2023-08-17T10:17:11.782+0000] {dagbag.py:538} INFO - Filling up the DagBag from /opt/airflow/dags/random_user_etl.py
[2023-08-17T10:17:15.810+0000] {logging_mixin.py:137} INFO - [2023-08-17T10:17:15.803+0000] {dagbag.py:343} ERROR - Failed to import: /opt/airflow/dags/random_user_etl.py
Traceback (most recent call last):
  File "/home/airflow/.local/lib/python3.7/site-packages/airflow/models/dagbag.py", line 339, in parse
    loader.exec_module(new_module)
  File "<frozen importlib._bootstrap_external>", line 728, in exec_module
  File "<frozen importlib._bootstrap>", line 219, in _call_with_frames_removed
  File "/opt/airflow/dags/random_user_etl.py", line 101, in <module>
    start_date=datetime(2023,16,1),
ValueError: month must be in 1..12
[2023-08-17T10:17:15.814+0000] {processor.py:755} WARNING - No viable dags retrieved from /opt/airflow/dags/random_user_etl.py
[2023-08-17T10:17:15.843+0000] {processor.py:175} INFO - Processing /opt/airflow/dags/random_user_etl.py took 4.095 seconds
[2023-08-17T10:17:46.045+0000] {processor.py:153} INFO - Started process (PID=2373) to work on /opt/airflow/dags/random_user_etl.py
[2023-08-17T10:17:46.048+0000] {processor.py:743} INFO - Processing file /opt/airflow/dags/random_user_etl.py for tasks to queue
[2023-08-17T10:17:46.050+0000] {logging_mixin.py:137} INFO - [2023-08-17T10:17:46.050+0000] {dagbag.py:538} INFO - Filling up the DagBag from /opt/airflow/dags/random_user_etl.py
[2023-08-17T10:17:49.348+0000] {logging_mixin.py:137} INFO - [2023-08-17T10:17:49.340+0000] {dagbag.py:343} ERROR - Failed to import: /opt/airflow/dags/random_user_etl.py
Traceback (most recent call last):
  File "/home/airflow/.local/lib/python3.7/site-packages/airflow/models/dagbag.py", line 339, in parse
    loader.exec_module(new_module)
  File "<frozen importlib._bootstrap_external>", line 728, in exec_module
  File "<frozen importlib._bootstrap>", line 219, in _call_with_frames_removed
  File "/opt/airflow/dags/random_user_etl.py", line 101, in <module>
    start_date=datetime(2023,16,1),
ValueError: month must be in 1..12
[2023-08-17T10:17:49.351+0000] {processor.py:755} WARNING - No viable dags retrieved from /opt/airflow/dags/random_user_etl.py
[2023-08-17T10:17:49.382+0000] {processor.py:175} INFO - Processing /opt/airflow/dags/random_user_etl.py took 3.341 seconds
[2023-08-17T10:18:19.713+0000] {processor.py:153} INFO - Started process (PID=2411) to work on /opt/airflow/dags/random_user_etl.py
[2023-08-17T10:18:19.716+0000] {processor.py:743} INFO - Processing file /opt/airflow/dags/random_user_etl.py for tasks to queue
[2023-08-17T10:18:19.717+0000] {logging_mixin.py:137} INFO - [2023-08-17T10:18:19.717+0000] {dagbag.py:538} INFO - Filling up the DagBag from /opt/airflow/dags/random_user_etl.py
[2023-08-17T10:18:23.007+0000] {logging_mixin.py:137} INFO - [2023-08-17T10:18:22.995+0000] {dagbag.py:343} ERROR - Failed to import: /opt/airflow/dags/random_user_etl.py
Traceback (most recent call last):
  File "/home/airflow/.local/lib/python3.7/site-packages/airflow/models/dagbag.py", line 339, in parse
    loader.exec_module(new_module)
  File "<frozen importlib._bootstrap_external>", line 728, in exec_module
  File "<frozen importlib._bootstrap>", line 219, in _call_with_frames_removed
  File "/opt/airflow/dags/random_user_etl.py", line 101, in <module>
    start_date=datetime(2023,16,1),
ValueError: month must be in 1..12
[2023-08-17T10:18:23.011+0000] {processor.py:755} WARNING - No viable dags retrieved from /opt/airflow/dags/random_user_etl.py
[2023-08-17T10:18:23.045+0000] {processor.py:175} INFO - Processing /opt/airflow/dags/random_user_etl.py took 3.336 seconds
[2023-08-17T10:18:53.322+0000] {processor.py:153} INFO - Started process (PID=2448) to work on /opt/airflow/dags/random_user_etl.py
[2023-08-17T10:18:53.324+0000] {processor.py:743} INFO - Processing file /opt/airflow/dags/random_user_etl.py for tasks to queue
[2023-08-17T10:18:53.325+0000] {logging_mixin.py:137} INFO - [2023-08-17T10:18:53.325+0000] {dagbag.py:538} INFO - Filling up the DagBag from /opt/airflow/dags/random_user_etl.py
[2023-08-17T10:18:56.401+0000] {logging_mixin.py:137} INFO - [2023-08-17T10:18:56.393+0000] {dagbag.py:343} ERROR - Failed to import: /opt/airflow/dags/random_user_etl.py
Traceback (most recent call last):
  File "/home/airflow/.local/lib/python3.7/site-packages/airflow/models/dagbag.py", line 339, in parse
    loader.exec_module(new_module)
  File "<frozen importlib._bootstrap_external>", line 728, in exec_module
  File "<frozen importlib._bootstrap>", line 219, in _call_with_frames_removed
  File "/opt/airflow/dags/random_user_etl.py", line 101, in <module>
    start_date=datetime(2023,16,1),
ValueError: month must be in 1..12
[2023-08-17T10:18:56.405+0000] {processor.py:755} WARNING - No viable dags retrieved from /opt/airflow/dags/random_user_etl.py
[2023-08-17T10:18:56.436+0000] {processor.py:175} INFO - Processing /opt/airflow/dags/random_user_etl.py took 3.118 seconds
[2023-08-17T10:19:26.682+0000] {processor.py:153} INFO - Started process (PID=2488) to work on /opt/airflow/dags/random_user_etl.py
[2023-08-17T10:19:26.684+0000] {processor.py:743} INFO - Processing file /opt/airflow/dags/random_user_etl.py for tasks to queue
[2023-08-17T10:19:26.685+0000] {logging_mixin.py:137} INFO - [2023-08-17T10:19:26.685+0000] {dagbag.py:538} INFO - Filling up the DagBag from /opt/airflow/dags/random_user_etl.py
[2023-08-17T10:19:29.962+0000] {logging_mixin.py:137} INFO - [2023-08-17T10:19:29.954+0000] {dagbag.py:343} ERROR - Failed to import: /opt/airflow/dags/random_user_etl.py
Traceback (most recent call last):
  File "/home/airflow/.local/lib/python3.7/site-packages/airflow/models/dagbag.py", line 339, in parse
    loader.exec_module(new_module)
  File "<frozen importlib._bootstrap_external>", line 728, in exec_module
  File "<frozen importlib._bootstrap>", line 219, in _call_with_frames_removed
  File "/opt/airflow/dags/random_user_etl.py", line 101, in <module>
    start_date=datetime(2023,16,1),
ValueError: month must be in 1..12
[2023-08-17T10:19:29.966+0000] {processor.py:755} WARNING - No viable dags retrieved from /opt/airflow/dags/random_user_etl.py
[2023-08-17T10:19:29.992+0000] {processor.py:175} INFO - Processing /opt/airflow/dags/random_user_etl.py took 3.313 seconds
[2023-08-17T10:20:00.158+0000] {processor.py:153} INFO - Started process (PID=2513) to work on /opt/airflow/dags/random_user_etl.py
[2023-08-17T10:20:00.161+0000] {processor.py:743} INFO - Processing file /opt/airflow/dags/random_user_etl.py for tasks to queue
[2023-08-17T10:20:00.163+0000] {logging_mixin.py:137} INFO - [2023-08-17T10:20:00.163+0000] {dagbag.py:538} INFO - Filling up the DagBag from /opt/airflow/dags/random_user_etl.py
[2023-08-17T10:20:03.316+0000] {logging_mixin.py:137} INFO - [2023-08-17T10:20:03.312+0000] {dagbag.py:343} ERROR - Failed to import: /opt/airflow/dags/random_user_etl.py
Traceback (most recent call last):
  File "/home/airflow/.local/lib/python3.7/site-packages/airflow/models/dagbag.py", line 339, in parse
    loader.exec_module(new_module)
  File "<frozen importlib._bootstrap_external>", line 728, in exec_module
  File "<frozen importlib._bootstrap>", line 219, in _call_with_frames_removed
  File "/opt/airflow/dags/random_user_etl.py", line 101, in <module>
    start_date=datetime(2023,16,1),
ValueError: month must be in 1..12
[2023-08-17T10:20:03.318+0000] {processor.py:755} WARNING - No viable dags retrieved from /opt/airflow/dags/random_user_etl.py
[2023-08-17T10:20:03.340+0000] {processor.py:175} INFO - Processing /opt/airflow/dags/random_user_etl.py took 3.188 seconds
[2023-08-17T10:20:33.559+0000] {processor.py:153} INFO - Started process (PID=2550) to work on /opt/airflow/dags/random_user_etl.py
[2023-08-17T10:20:33.562+0000] {processor.py:743} INFO - Processing file /opt/airflow/dags/random_user_etl.py for tasks to queue
[2023-08-17T10:20:33.564+0000] {logging_mixin.py:137} INFO - [2023-08-17T10:20:33.564+0000] {dagbag.py:538} INFO - Filling up the DagBag from /opt/airflow/dags/random_user_etl.py
[2023-08-17T10:20:37.489+0000] {logging_mixin.py:137} INFO - [2023-08-17T10:20:37.484+0000] {dagbag.py:343} ERROR - Failed to import: /opt/airflow/dags/random_user_etl.py
Traceback (most recent call last):
  File "/home/airflow/.local/lib/python3.7/site-packages/airflow/models/dagbag.py", line 339, in parse
    loader.exec_module(new_module)
  File "<frozen importlib._bootstrap_external>", line 728, in exec_module
  File "<frozen importlib._bootstrap>", line 219, in _call_with_frames_removed
  File "/opt/airflow/dags/random_user_etl.py", line 101, in <module>
    start_date=datetime(2023,16,1),
ValueError: month must be in 1..12
[2023-08-17T10:20:37.492+0000] {processor.py:755} WARNING - No viable dags retrieved from /opt/airflow/dags/random_user_etl.py
[2023-08-17T10:20:37.518+0000] {processor.py:175} INFO - Processing /opt/airflow/dags/random_user_etl.py took 3.963 seconds
[2023-08-17T10:21:08.012+0000] {processor.py:153} INFO - Started process (PID=2588) to work on /opt/airflow/dags/random_user_etl.py
[2023-08-17T10:21:08.016+0000] {processor.py:743} INFO - Processing file /opt/airflow/dags/random_user_etl.py for tasks to queue
[2023-08-17T10:21:08.019+0000] {logging_mixin.py:137} INFO - [2023-08-17T10:21:08.018+0000] {dagbag.py:538} INFO - Filling up the DagBag from /opt/airflow/dags/random_user_etl.py
[2023-08-17T10:21:11.256+0000] {logging_mixin.py:137} INFO - [2023-08-17T10:21:11.252+0000] {dagbag.py:343} ERROR - Failed to import: /opt/airflow/dags/random_user_etl.py
Traceback (most recent call last):
  File "/home/airflow/.local/lib/python3.7/site-packages/airflow/models/dagbag.py", line 339, in parse
    loader.exec_module(new_module)
  File "<frozen importlib._bootstrap_external>", line 728, in exec_module
  File "<frozen importlib._bootstrap>", line 219, in _call_with_frames_removed
  File "/opt/airflow/dags/random_user_etl.py", line 101, in <module>
    start_date=datetime(2023,16,1),
ValueError: month must be in 1..12
[2023-08-17T10:21:11.258+0000] {processor.py:755} WARNING - No viable dags retrieved from /opt/airflow/dags/random_user_etl.py
[2023-08-17T10:21:11.306+0000] {processor.py:175} INFO - Processing /opt/airflow/dags/random_user_etl.py took 3.300 seconds
[2023-08-17T10:21:41.411+0000] {processor.py:153} INFO - Started process (PID=2627) to work on /opt/airflow/dags/random_user_etl.py
[2023-08-17T10:21:41.413+0000] {processor.py:743} INFO - Processing file /opt/airflow/dags/random_user_etl.py for tasks to queue
[2023-08-17T10:21:41.414+0000] {logging_mixin.py:137} INFO - [2023-08-17T10:21:41.414+0000] {dagbag.py:538} INFO - Filling up the DagBag from /opt/airflow/dags/random_user_etl.py
[2023-08-17T10:21:44.546+0000] {logging_mixin.py:137} INFO - [2023-08-17T10:21:44.544+0000] {dagbag.py:343} ERROR - Failed to import: /opt/airflow/dags/random_user_etl.py
Traceback (most recent call last):
  File "/home/airflow/.local/lib/python3.7/site-packages/airflow/models/dagbag.py", line 339, in parse
    loader.exec_module(new_module)
  File "<frozen importlib._bootstrap_external>", line 728, in exec_module
  File "<frozen importlib._bootstrap>", line 219, in _call_with_frames_removed
  File "/opt/airflow/dags/random_user_etl.py", line 101, in <module>
    start_date=datetime(2023,16,1),
ValueError: month must be in 1..12
[2023-08-17T10:21:44.548+0000] {processor.py:755} WARNING - No viable dags retrieved from /opt/airflow/dags/random_user_etl.py
[2023-08-17T10:21:44.564+0000] {processor.py:175} INFO - Processing /opt/airflow/dags/random_user_etl.py took 3.157 seconds
[2023-08-17T10:22:14.871+0000] {processor.py:153} INFO - Started process (PID=2666) to work on /opt/airflow/dags/random_user_etl.py
[2023-08-17T10:22:14.873+0000] {processor.py:743} INFO - Processing file /opt/airflow/dags/random_user_etl.py for tasks to queue
[2023-08-17T10:22:14.875+0000] {logging_mixin.py:137} INFO - [2023-08-17T10:22:14.875+0000] {dagbag.py:538} INFO - Filling up the DagBag from /opt/airflow/dags/random_user_etl.py
[2023-08-17T10:22:18.168+0000] {logging_mixin.py:137} INFO - [2023-08-17T10:22:18.165+0000] {dagbag.py:343} ERROR - Failed to import: /opt/airflow/dags/random_user_etl.py
Traceback (most recent call last):
  File "/home/airflow/.local/lib/python3.7/site-packages/airflow/models/dagbag.py", line 339, in parse
    loader.exec_module(new_module)
  File "<frozen importlib._bootstrap_external>", line 728, in exec_module
  File "<frozen importlib._bootstrap>", line 219, in _call_with_frames_removed
  File "/opt/airflow/dags/random_user_etl.py", line 101, in <module>
    start_date=datetime(2023,16,1),
ValueError: month must be in 1..12
[2023-08-17T10:22:18.169+0000] {processor.py:755} WARNING - No viable dags retrieved from /opt/airflow/dags/random_user_etl.py
[2023-08-17T10:22:18.186+0000] {processor.py:175} INFO - Processing /opt/airflow/dags/random_user_etl.py took 3.320 seconds
[2023-08-17T10:22:48.480+0000] {processor.py:153} INFO - Started process (PID=2704) to work on /opt/airflow/dags/random_user_etl.py
[2023-08-17T10:22:48.484+0000] {processor.py:743} INFO - Processing file /opt/airflow/dags/random_user_etl.py for tasks to queue
[2023-08-17T10:22:48.486+0000] {logging_mixin.py:137} INFO - [2023-08-17T10:22:48.486+0000] {dagbag.py:538} INFO - Filling up the DagBag from /opt/airflow/dags/random_user_etl.py
[2023-08-17T10:22:51.759+0000] {logging_mixin.py:137} INFO - [2023-08-17T10:22:51.756+0000] {dagbag.py:343} ERROR - Failed to import: /opt/airflow/dags/random_user_etl.py
Traceback (most recent call last):
  File "/home/airflow/.local/lib/python3.7/site-packages/airflow/models/dagbag.py", line 339, in parse
    loader.exec_module(new_module)
  File "<frozen importlib._bootstrap_external>", line 728, in exec_module
  File "<frozen importlib._bootstrap>", line 219, in _call_with_frames_removed
  File "/opt/airflow/dags/random_user_etl.py", line 101, in <module>
    start_date=datetime(2023,16,1),
ValueError: month must be in 1..12
[2023-08-17T10:22:51.760+0000] {processor.py:755} WARNING - No viable dags retrieved from /opt/airflow/dags/random_user_etl.py
[2023-08-17T10:22:51.777+0000] {processor.py:175} INFO - Processing /opt/airflow/dags/random_user_etl.py took 3.303 seconds
[2023-08-17T10:23:21.906+0000] {processor.py:153} INFO - Started process (PID=2744) to work on /opt/airflow/dags/random_user_etl.py
[2023-08-17T10:23:21.910+0000] {processor.py:743} INFO - Processing file /opt/airflow/dags/random_user_etl.py for tasks to queue
[2023-08-17T10:23:21.912+0000] {logging_mixin.py:137} INFO - [2023-08-17T10:23:21.912+0000] {dagbag.py:538} INFO - Filling up the DagBag from /opt/airflow/dags/random_user_etl.py
[2023-08-17T10:38:06.927+0000] {processor.py:153} INFO - Started process (PID=33) to work on /opt/airflow/dags/random_user_etl.py
[2023-08-17T10:38:06.929+0000] {processor.py:743} INFO - Processing file /opt/airflow/dags/random_user_etl.py for tasks to queue
[2023-08-17T10:38:06.930+0000] {logging_mixin.py:137} INFO - [2023-08-17T10:38:06.930+0000] {dagbag.py:538} INFO - Filling up the DagBag from /opt/airflow/dags/random_user_etl.py
[2023-08-17T10:38:10.951+0000] {logging_mixin.py:137} INFO - [2023-08-17T10:38:10.944+0000] {dagbag.py:343} ERROR - Failed to import: /opt/airflow/dags/random_user_etl.py
Traceback (most recent call last):
  File "/home/airflow/.local/lib/python3.7/site-packages/airflow/models/dagbag.py", line 339, in parse
    loader.exec_module(new_module)
  File "<frozen importlib._bootstrap_external>", line 728, in exec_module
  File "<frozen importlib._bootstrap>", line 219, in _call_with_frames_removed
  File "/opt/airflow/dags/random_user_etl.py", line 101, in <module>
    start_date=datetime(2023,16,1),
ValueError: month must be in 1..12
[2023-08-17T10:38:10.962+0000] {processor.py:755} WARNING - No viable dags retrieved from /opt/airflow/dags/random_user_etl.py
[2023-08-17T10:38:11.017+0000] {processor.py:175} INFO - Processing /opt/airflow/dags/random_user_etl.py took 4.092 seconds
[2023-08-17T10:38:41.446+0000] {processor.py:153} INFO - Started process (PID=70) to work on /opt/airflow/dags/random_user_etl.py
[2023-08-17T10:38:41.451+0000] {processor.py:743} INFO - Processing file /opt/airflow/dags/random_user_etl.py for tasks to queue
[2023-08-17T10:38:41.455+0000] {logging_mixin.py:137} INFO - [2023-08-17T10:38:41.454+0000] {dagbag.py:538} INFO - Filling up the DagBag from /opt/airflow/dags/random_user_etl.py
[2023-08-17T10:38:52.281+0000] {logging_mixin.py:137} INFO - [2023-08-17T10:38:52.270+0000] {dagbag.py:343} ERROR - Failed to import: /opt/airflow/dags/random_user_etl.py
Traceback (most recent call last):
  File "/home/airflow/.local/lib/python3.7/site-packages/airflow/models/dagbag.py", line 339, in parse
    loader.exec_module(new_module)
  File "<frozen importlib._bootstrap_external>", line 728, in exec_module
  File "<frozen importlib._bootstrap>", line 219, in _call_with_frames_removed
  File "/opt/airflow/dags/random_user_etl.py", line 101, in <module>
    start_date=datetime(2023,16,1),
ValueError: month must be in 1..12
[2023-08-17T10:38:52.284+0000] {processor.py:755} WARNING - No viable dags retrieved from /opt/airflow/dags/random_user_etl.py
[2023-08-17T10:38:52.342+0000] {processor.py:175} INFO - Processing /opt/airflow/dags/random_user_etl.py took 10.899 seconds
[2023-08-17T10:39:22.554+0000] {processor.py:153} INFO - Started process (PID=109) to work on /opt/airflow/dags/random_user_etl.py
[2023-08-17T10:39:22.558+0000] {processor.py:743} INFO - Processing file /opt/airflow/dags/random_user_etl.py for tasks to queue
[2023-08-17T10:39:22.561+0000] {logging_mixin.py:137} INFO - [2023-08-17T10:39:22.561+0000] {dagbag.py:538} INFO - Filling up the DagBag from /opt/airflow/dags/random_user_etl.py
[2023-08-17T10:39:29.975+0000] {logging_mixin.py:137} INFO - [2023-08-17T10:39:29.962+0000] {dagbag.py:343} ERROR - Failed to import: /opt/airflow/dags/random_user_etl.py
Traceback (most recent call last):
  File "/home/airflow/.local/lib/python3.7/site-packages/airflow/models/dagbag.py", line 339, in parse
    loader.exec_module(new_module)
  File "<frozen importlib._bootstrap_external>", line 728, in exec_module
  File "<frozen importlib._bootstrap>", line 219, in _call_with_frames_removed
  File "/opt/airflow/dags/random_user_etl.py", line 101, in <module>
    start_date=datetime(2023,16,1),
ValueError: month must be in 1..12
[2023-08-17T10:39:29.977+0000] {processor.py:755} WARNING - No viable dags retrieved from /opt/airflow/dags/random_user_etl.py
[2023-08-17T10:39:29.999+0000] {processor.py:175} INFO - Processing /opt/airflow/dags/random_user_etl.py took 7.448 seconds
[2023-08-17T10:40:00.143+0000] {processor.py:153} INFO - Started process (PID=146) to work on /opt/airflow/dags/random_user_etl.py
[2023-08-17T10:40:00.146+0000] {processor.py:743} INFO - Processing file /opt/airflow/dags/random_user_etl.py for tasks to queue
[2023-08-17T10:40:00.147+0000] {logging_mixin.py:137} INFO - [2023-08-17T10:40:00.147+0000] {dagbag.py:538} INFO - Filling up the DagBag from /opt/airflow/dags/random_user_etl.py
[2023-08-17T10:40:11.222+0000] {logging_mixin.py:137} INFO - [2023-08-17T10:40:11.213+0000] {dagbag.py:343} ERROR - Failed to import: /opt/airflow/dags/random_user_etl.py
Traceback (most recent call last):
  File "/home/airflow/.local/lib/python3.7/site-packages/airflow/models/dagbag.py", line 339, in parse
    loader.exec_module(new_module)
  File "<frozen importlib._bootstrap_external>", line 728, in exec_module
  File "<frozen importlib._bootstrap>", line 219, in _call_with_frames_removed
  File "/opt/airflow/dags/random_user_etl.py", line 101, in <module>
    start_date=datetime(2023,16,1),
ValueError: month must be in 1..12
[2023-08-17T10:40:11.225+0000] {processor.py:755} WARNING - No viable dags retrieved from /opt/airflow/dags/random_user_etl.py
[2023-08-17T10:40:11.286+0000] {processor.py:175} INFO - Processing /opt/airflow/dags/random_user_etl.py took 11.146 seconds
[2023-08-17T10:40:41.551+0000] {processor.py:153} INFO - Started process (PID=184) to work on /opt/airflow/dags/random_user_etl.py
[2023-08-17T10:40:41.552+0000] {processor.py:743} INFO - Processing file /opt/airflow/dags/random_user_etl.py for tasks to queue
[2023-08-17T10:40:41.554+0000] {logging_mixin.py:137} INFO - [2023-08-17T10:40:41.553+0000] {dagbag.py:538} INFO - Filling up the DagBag from /opt/airflow/dags/random_user_etl.py
[2023-08-17T10:40:51.389+0000] {logging_mixin.py:137} INFO - [2023-08-17T10:40:51.379+0000] {dagbag.py:343} ERROR - Failed to import: /opt/airflow/dags/random_user_etl.py
Traceback (most recent call last):
  File "/home/airflow/.local/lib/python3.7/site-packages/airflow/models/dagbag.py", line 339, in parse
    loader.exec_module(new_module)
  File "<frozen importlib._bootstrap_external>", line 728, in exec_module
  File "<frozen importlib._bootstrap>", line 219, in _call_with_frames_removed
  File "/opt/airflow/dags/random_user_etl.py", line 101, in <module>
    start_date=datetime(2023,16,1),
ValueError: month must be in 1..12
[2023-08-17T10:40:51.393+0000] {processor.py:755} WARNING - No viable dags retrieved from /opt/airflow/dags/random_user_etl.py
[2023-08-17T10:40:51.539+0000] {processor.py:175} INFO - Processing /opt/airflow/dags/random_user_etl.py took 9.992 seconds
[2023-08-17T10:41:21.976+0000] {processor.py:153} INFO - Started process (PID=221) to work on /opt/airflow/dags/random_user_etl.py
[2023-08-17T10:41:21.997+0000] {processor.py:743} INFO - Processing file /opt/airflow/dags/random_user_etl.py for tasks to queue
[2023-08-17T10:41:22.000+0000] {logging_mixin.py:137} INFO - [2023-08-17T10:41:22.000+0000] {dagbag.py:538} INFO - Filling up the DagBag from /opt/airflow/dags/random_user_etl.py
[2023-08-17T10:41:31.059+0000] {logging_mixin.py:137} INFO - [2023-08-17T10:41:31.049+0000] {dagbag.py:343} ERROR - Failed to import: /opt/airflow/dags/random_user_etl.py
Traceback (most recent call last):
  File "/home/airflow/.local/lib/python3.7/site-packages/airflow/models/dagbag.py", line 339, in parse
    loader.exec_module(new_module)
  File "<frozen importlib._bootstrap_external>", line 728, in exec_module
  File "<frozen importlib._bootstrap>", line 219, in _call_with_frames_removed
  File "/opt/airflow/dags/random_user_etl.py", line 101, in <module>
    start_date=datetime(2023,16,1),
ValueError: month must be in 1..12
[2023-08-17T10:41:31.065+0000] {processor.py:755} WARNING - No viable dags retrieved from /opt/airflow/dags/random_user_etl.py
[2023-08-17T10:41:31.581+0000] {processor.py:175} INFO - Processing /opt/airflow/dags/random_user_etl.py took 9.630 seconds
[2023-08-17T10:42:02.105+0000] {processor.py:153} INFO - Started process (PID=257) to work on /opt/airflow/dags/random_user_etl.py
[2023-08-17T10:42:02.109+0000] {processor.py:743} INFO - Processing file /opt/airflow/dags/random_user_etl.py for tasks to queue
[2023-08-17T10:42:02.114+0000] {logging_mixin.py:137} INFO - [2023-08-17T10:42:02.114+0000] {dagbag.py:538} INFO - Filling up the DagBag from /opt/airflow/dags/random_user_etl.py
[2023-08-17T10:42:12.575+0000] {logging_mixin.py:137} INFO - [2023-08-17T10:42:12.566+0000] {dagbag.py:343} ERROR - Failed to import: /opt/airflow/dags/random_user_etl.py
Traceback (most recent call last):
  File "/home/airflow/.local/lib/python3.7/site-packages/airflow/models/dagbag.py", line 339, in parse
    loader.exec_module(new_module)
  File "<frozen importlib._bootstrap_external>", line 728, in exec_module
  File "<frozen importlib._bootstrap>", line 219, in _call_with_frames_removed
  File "/opt/airflow/dags/random_user_etl.py", line 101, in <module>
    start_date=datetime(2023,16,1),
ValueError: month must be in 1..12
[2023-08-17T10:42:12.579+0000] {processor.py:755} WARNING - No viable dags retrieved from /opt/airflow/dags/random_user_etl.py
[2023-08-17T10:42:12.605+0000] {processor.py:175} INFO - Processing /opt/airflow/dags/random_user_etl.py took 10.520 seconds
[2023-08-17T10:42:42.911+0000] {processor.py:153} INFO - Started process (PID=295) to work on /opt/airflow/dags/random_user_etl.py
[2023-08-17T10:42:42.919+0000] {processor.py:743} INFO - Processing file /opt/airflow/dags/random_user_etl.py for tasks to queue
[2023-08-17T10:42:42.922+0000] {logging_mixin.py:137} INFO - [2023-08-17T10:42:42.922+0000] {dagbag.py:538} INFO - Filling up the DagBag from /opt/airflow/dags/random_user_etl.py
[2023-08-17T10:42:53.124+0000] {logging_mixin.py:137} INFO - [2023-08-17T10:42:53.113+0000] {dagbag.py:343} ERROR - Failed to import: /opt/airflow/dags/random_user_etl.py
Traceback (most recent call last):
  File "/home/airflow/.local/lib/python3.7/site-packages/airflow/models/dagbag.py", line 339, in parse
    loader.exec_module(new_module)
  File "<frozen importlib._bootstrap_external>", line 728, in exec_module
  File "<frozen importlib._bootstrap>", line 219, in _call_with_frames_removed
  File "/opt/airflow/dags/random_user_etl.py", line 101, in <module>
    start_date=datetime(2023,16,1),
ValueError: month must be in 1..12
[2023-08-17T10:42:53.126+0000] {processor.py:755} WARNING - No viable dags retrieved from /opt/airflow/dags/random_user_etl.py
[2023-08-17T10:42:53.208+0000] {processor.py:175} INFO - Processing /opt/airflow/dags/random_user_etl.py took 10.320 seconds
[2023-08-17T10:43:23.500+0000] {processor.py:153} INFO - Started process (PID=332) to work on /opt/airflow/dags/random_user_etl.py
[2023-08-17T10:43:23.503+0000] {processor.py:743} INFO - Processing file /opt/airflow/dags/random_user_etl.py for tasks to queue
[2023-08-17T10:43:23.505+0000] {logging_mixin.py:137} INFO - [2023-08-17T10:43:23.504+0000] {dagbag.py:538} INFO - Filling up the DagBag from /opt/airflow/dags/random_user_etl.py
[2023-08-17T10:43:32.631+0000] {logging_mixin.py:137} INFO - [2023-08-17T10:43:32.628+0000] {dagbag.py:343} ERROR - Failed to import: /opt/airflow/dags/random_user_etl.py
Traceback (most recent call last):
  File "/home/airflow/.local/lib/python3.7/site-packages/airflow/models/dagbag.py", line 339, in parse
    loader.exec_module(new_module)
  File "<frozen importlib._bootstrap_external>", line 728, in exec_module
  File "<frozen importlib._bootstrap>", line 219, in _call_with_frames_removed
  File "/opt/airflow/dags/random_user_etl.py", line 101, in <module>
    start_date=datetime(2023,16,1),
ValueError: month must be in 1..12
[2023-08-17T10:43:32.632+0000] {processor.py:755} WARNING - No viable dags retrieved from /opt/airflow/dags/random_user_etl.py
[2023-08-17T10:43:32.654+0000] {processor.py:175} INFO - Processing /opt/airflow/dags/random_user_etl.py took 9.158 seconds
[2023-08-17T10:44:02.904+0000] {processor.py:153} INFO - Started process (PID=370) to work on /opt/airflow/dags/random_user_etl.py
[2023-08-17T10:44:02.907+0000] {processor.py:743} INFO - Processing file /opt/airflow/dags/random_user_etl.py for tasks to queue
[2023-08-17T10:44:02.910+0000] {logging_mixin.py:137} INFO - [2023-08-17T10:44:02.910+0000] {dagbag.py:538} INFO - Filling up the DagBag from /opt/airflow/dags/random_user_etl.py
[2023-08-17T10:44:13.693+0000] {logging_mixin.py:137} INFO - [2023-08-17T10:44:13.688+0000] {dagbag.py:343} ERROR - Failed to import: /opt/airflow/dags/random_user_etl.py
Traceback (most recent call last):
  File "/home/airflow/.local/lib/python3.7/site-packages/airflow/models/dagbag.py", line 339, in parse
    loader.exec_module(new_module)
  File "<frozen importlib._bootstrap_external>", line 728, in exec_module
  File "<frozen importlib._bootstrap>", line 219, in _call_with_frames_removed
  File "/opt/airflow/dags/random_user_etl.py", line 101, in <module>
    start_date=datetime(2023,16,1),
ValueError: month must be in 1..12
[2023-08-17T10:44:13.695+0000] {processor.py:755} WARNING - No viable dags retrieved from /opt/airflow/dags/random_user_etl.py
[2023-08-17T10:44:13.716+0000] {processor.py:175} INFO - Processing /opt/airflow/dags/random_user_etl.py took 10.817 seconds
