[2023-08-16T09:07:07.049+0000] {taskinstance.py:1087} INFO - Dependencies all met for <TaskInstance: rapid_api_v1.load_db scheduled__2023-08-01T00:00:00+00:00 [queued]>
[2023-08-16T09:07:07.068+0000] {taskinstance.py:1087} INFO - Dependencies all met for <TaskInstance: rapid_api_v1.load_db scheduled__2023-08-01T00:00:00+00:00 [queued]>
[2023-08-16T09:07:07.069+0000] {taskinstance.py:1283} INFO - 
--------------------------------------------------------------------------------
[2023-08-16T09:07:07.070+0000] {taskinstance.py:1284} INFO - Starting attempt 1 of 1
[2023-08-16T09:07:07.072+0000] {taskinstance.py:1285} INFO - 
--------------------------------------------------------------------------------
[2023-08-16T09:07:07.087+0000] {taskinstance.py:1304} INFO - Executing <Task(PythonOperator): load_db> on 2023-08-01 00:00:00+00:00
[2023-08-16T09:07:07.094+0000] {standard_task_runner.py:55} INFO - Started process 354 to run task
[2023-08-16T09:07:07.108+0000] {standard_task_runner.py:82} INFO - Running: ['***', 'tasks', 'run', 'rapid_api_v1', 'load_db', 'scheduled__2023-08-01T00:00:00+00:00', '--job-id', '27', '--raw', '--subdir', 'DAGS_FOLDER/jobs_etl.py', '--cfg-path', '/tmp/tmp8b1or5g6']
[2023-08-16T09:07:07.112+0000] {standard_task_runner.py:83} INFO - Job 27: Subtask load_db
[2023-08-16T09:07:07.191+0000] {task_command.py:389} INFO - Running <TaskInstance: rapid_api_v1.load_db scheduled__2023-08-01T00:00:00+00:00 [running]> on host 17c4b1dd2309
[2023-08-16T09:07:07.288+0000] {taskinstance.py:1513} INFO - Exporting the following env vars:
AIRFLOW_CTX_DAG_OWNER=***
AIRFLOW_CTX_DAG_ID=rapid_api_v1
AIRFLOW_CTX_TASK_ID=load_db
AIRFLOW_CTX_EXECUTION_DATE=2023-08-01T00:00:00+00:00
AIRFLOW_CTX_TRY_NUMBER=1
AIRFLOW_CTX_DAG_RUN_ID=scheduled__2023-08-01T00:00:00+00:00
[2023-08-16T09:07:07.342+0000] {taskinstance.py:1772} ERROR - Task failed with exception
Traceback (most recent call last):
  File "/home/airflow/.local/lib/python3.7/site-packages/airflow/operators/python.py", line 175, in execute
    return_value = self.execute_callable()
  File "/home/airflow/.local/lib/python3.7/site-packages/airflow/operators/python.py", line 192, in execute_callable
    return self.python_callable(*self.op_args, **self.op_kwargs)
  File "/opt/airflow/dags/jobs_etl.py", line 122, in to_sql_task
    df.to_sql(table_name, engine)
  File "/home/airflow/.local/lib/python3.7/site-packages/pandas/core/generic.py", line 2882, in to_sql
    method=method,
  File "/home/airflow/.local/lib/python3.7/site-packages/pandas/io/sql.py", line 728, in to_sql
    **engine_kwargs,
  File "/home/airflow/.local/lib/python3.7/site-packages/pandas/io/sql.py", line 1758, in to_sql
    dtype=dtype,
  File "/home/airflow/.local/lib/python3.7/site-packages/pandas/io/sql.py", line 1650, in prep_table
    table.create()
  File "/home/airflow/.local/lib/python3.7/site-packages/pandas/io/sql.py", line 858, in create
    raise ValueError(f"Table '{self.name}' already exists.")
ValueError: Table 'new_rapid_api_jobs' already exists.
[2023-08-16T09:07:07.364+0000] {taskinstance.py:1327} INFO - Marking task as FAILED. dag_id=rapid_api_v1, task_id=load_db, execution_date=20230801T000000, start_date=20230816T090707, end_date=20230816T090707
[2023-08-16T09:07:07.382+0000] {standard_task_runner.py:105} ERROR - Failed to execute job 27 for task load_db (Table 'new_rapid_api_jobs' already exists.; 354)
[2023-08-16T09:07:07.435+0000] {local_task_job.py:159} INFO - Task exited with return code 1
[2023-08-16T09:07:07.475+0000] {taskinstance.py:2582} INFO - 0 downstream tasks scheduled from follow-on schedule check
